########################################################################################################################
2019-10-31 10:09:54.171 | INFO  | some_module               : test_function        : 12   | 0
2019-10-31 10:09:54.171 | INFO  | some_module               : test_function        : 12   | 1
2019-10-31 10:09:54.172 | INFO  | some_module               : test_function        : 12   | 2
2019-10-31 10:09:54.172 | INFO  | some_module               : test_function        : 12   | 3
2019-10-31 10:09:54.172 | INFO  | some_module               : test_function        : 12   | 4
2019-10-31 10:09:54.172 | INFO  | some_module               : test_function        : 12   | 5
2019-10-31 10:09:54.173 | INFO  | some_module               : test_function        : 12   | 6
2019-10-31 10:09:54.173 | INFO  | some_module               : test_function        : 12   | 7
2019-10-31 10:09:54.173 | INFO  | some_module               : test_function        : 12   | 8
2019-10-31 10:09:54.173 | INFO  | some_module               : test_function        : 12   | 9
2019-10-31 10:09:55.175 | ERROR | log_to_file               : log_to_file          : 95   | An error has been caught in function 'log_to_file', process 'MainProcess' (25104), thread 'MainThread' (18224):
Traceback (most recent call last):

  File "D:\Users\JCHANGI\Jason Chang\Work\Others\code\log_to_file\package\log_to_file\log_to_file.py", line 95, in log_to_file
    everything_you_want_to_see = call_function(function)
                                 ¢x             ¢| <function <lambda> at 0x00000176E55DF598>
                                 ¢| <function call_function at 0x00000176E66497B8>

  File "D:\Users\JCHANGI\Jason Chang\Work\Others\code\log_to_file\package\log_to_file\log_to_file.py", line 33, in call_function
    return function()
           ¢| <function <lambda> at 0x00000176E55DF598>

  File "D:/Users/JCHANGI/Jason Chang/Work/Others/code/log_to_file/some_module_caller_example.py", line 18, in <lambda>
    everything_you_want_to_see = log_to_file(lambda : main(), print_opt = 0)
    ¢x                            ¢x                    ¢| <function main at 0x00000176E65E32F0>
    ¢x                            ¢| <function log_to_file at 0x00000176E6649A60>
    ¢| None

  File "D:/Users/JCHANGI/Jason Chang/Work/Others/code/log_to_file/some_module_caller_example.py", line 10, in main
    test_function(number)
    ¢x             ¢| 10
    ¢| <function test_function at 0x00000176E6649AE8>

  File "D:\Users\JCHANGI\Jason Chang\Work\Others\code\log_to_file\some_module.py", line 14, in test_function
    1/0

ZeroDivisionError: division by zero
########################################################################################################################
2019-10-31 10:11:02.371 | INFO  | some_module               : test_function        : 12   | 0
2019-10-31 10:11:02.371 | INFO  | some_module               : test_function        : 12   | 1
2019-10-31 10:11:02.371 | INFO  | some_module               : test_function        : 12   | 2
2019-10-31 10:11:02.372 | INFO  | some_module               : test_function        : 12   | 3
2019-10-31 10:11:02.372 | INFO  | some_module               : test_function        : 12   | 4
2019-10-31 10:11:02.372 | INFO  | some_module               : test_function        : 12   | 5
2019-10-31 10:11:02.372 | INFO  | some_module               : test_function        : 12   | 6
2019-10-31 10:11:02.372 | INFO  | some_module               : test_function        : 12   | 7
2019-10-31 10:11:02.372 | INFO  | some_module               : test_function        : 12   | 8
2019-10-31 10:11:02.372 | INFO  | some_module               : test_function        : 12   | 9
2019-10-31 10:11:03.375 | ERROR | log_to_file               : log_to_file          : 95   | An error has been caught in function 'log_to_file', process 'MainProcess' (25104), thread 'MainThread' (18224):
Traceback (most recent call last):

  File "D:\Users\JCHANGI\Jason Chang\Work\Others\code\log_to_file\package\log_to_file\log_to_file.py", line 95, in log_to_file
    everything_you_want_to_see = call_function(function)
                                 ¢x             ¢| <function <lambda> at 0x00000176E65E32F0>
                                 ¢| <function call_function at 0x00000176E6690488>

  File "D:\Users\JCHANGI\Jason Chang\Work\Others\code\log_to_file\package\log_to_file\log_to_file.py", line 33, in call_function
    return function()
           ¢| <function <lambda> at 0x00000176E65E32F0>

  File "D:/Users/JCHANGI/Jason Chang/Work/Others/code/log_to_file/some_module_caller_example.py", line 18, in <lambda>
    everything_you_want_to_see = log_to_file(lambda : main(), print_opt = 0)
    ¢x                            ¢x                    ¢| <function main at 0x00000176E55DFAE8>
    ¢x                            ¢| <function log_to_file at 0x00000176E6690730>
    ¢| None

  File "D:/Users/JCHANGI/Jason Chang/Work/Others/code/log_to_file/some_module_caller_example.py", line 10, in main
    test_function(number)
    ¢x             ¢| 10
    ¢| <function test_function at 0x00000176E66907B8>

  File "D:\Users\JCHANGI\Jason Chang\Work\Others\code\log_to_file\some_module.py", line 14, in test_function
    1/0

ZeroDivisionError: division by zero
########################################################################################################################
2019-10-31 10:14:13.286 | INFO  | some_module               : test_function        : 12   | 0
2019-10-31 10:14:13.286 | INFO  | some_module               : test_function        : 12   | 1
2019-10-31 10:14:13.286 | INFO  | some_module               : test_function        : 12   | 2
2019-10-31 10:14:13.286 | INFO  | some_module               : test_function        : 12   | 3
2019-10-31 10:14:13.286 | INFO  | some_module               : test_function        : 12   | 4
2019-10-31 10:14:13.286 | INFO  | some_module               : test_function        : 12   | 5
2019-10-31 10:14:13.286 | INFO  | some_module               : test_function        : 12   | 6
2019-10-31 10:14:13.287 | INFO  | some_module               : test_function        : 12   | 7
2019-10-31 10:14:13.287 | INFO  | some_module               : test_function        : 12   | 8
2019-10-31 10:14:13.287 | INFO  | some_module               : test_function        : 12   | 9
2019-10-31 10:14:14.289 | ERROR | log_to_file               : log_to_file          : 99   | An error has been caught in function 'log_to_file', process 'MainProcess' (25104), thread 'MainThread' (18224):
Traceback (most recent call last):

  File "D:\Users\JCHANGI\Jason Chang\Work\Others\code\log_to_file\package\log_to_file\log_to_file.py", line 99, in log_to_file
    everything_you_want_to_see = call_function(function)
                                 ¢x             ¢| <function <lambda> at 0x00000176E55DFAE8>
                                 ¢| <function call_function at 0x00000176E66C91E0>

  File "D:\Users\JCHANGI\Jason Chang\Work\Others\code\log_to_file\package\log_to_file\log_to_file.py", line 36, in call_function
    return function()
           ¢| <function <lambda> at 0x00000176E55DFAE8>

  File "D:/Users/JCHANGI/Jason Chang/Work/Others/code/log_to_file/some_module_caller_example.py", line 18, in <lambda>
    everything_you_want_to_see = log_to_file(lambda : main(), print_opt = 0)
    ¢x                            ¢x                    ¢| <function main at 0x00000176E66496A8>
    ¢x                            ¢| <function log_to_file at 0x00000176E66C9488>
    ¢| None

  File "D:/Users/JCHANGI/Jason Chang/Work/Others/code/log_to_file/some_module_caller_example.py", line 10, in main
    test_function(number)
    ¢x             ¢| 10
    ¢| <function test_function at 0x00000176E66C9510>

  File "D:\Users\JCHANGI\Jason Chang\Work\Others\code\log_to_file\some_module.py", line 14, in test_function
    1/0

ZeroDivisionError: division by zero
########################################################################################################################
2019-10-31 10:14:58.511 | INFO  | some_module               : test_function        : 12   | 0
2019-10-31 10:14:58.512 | INFO  | some_module               : test_function        : 12   | 1
2019-10-31 10:14:58.512 | INFO  | some_module               : test_function        : 12   | 2
2019-10-31 10:14:58.512 | INFO  | some_module               : test_function        : 12   | 3
2019-10-31 10:14:58.512 | INFO  | some_module               : test_function        : 12   | 4
2019-10-31 10:14:58.513 | INFO  | some_module               : test_function        : 12   | 5
2019-10-31 10:14:58.513 | INFO  | some_module               : test_function        : 12   | 6
2019-10-31 10:14:58.513 | INFO  | some_module               : test_function        : 12   | 7
2019-10-31 10:14:58.513 | INFO  | some_module               : test_function        : 12   | 8
2019-10-31 10:14:58.513 | INFO  | some_module               : test_function        : 12   | 9
2019-10-31 10:14:59.514 | ERROR | log_to_file               : log_to_file          : 99   | An error has been caught in function 'log_to_file', process 'MainProcess' (25104), thread 'MainThread' (18224):
Traceback (most recent call last):

  File "D:\Users\JCHANGI\Jason Chang\Work\Others\code\log_to_file\package\log_to_file\log_to_file.py", line 99, in log_to_file
    everything_you_want_to_see = call_function(function)
                                 ¢x             ¢| <function <lambda> at 0x00000176E66496A8>
                                 ¢| <function call_function at 0x00000176E6710F28>

  File "D:\Users\JCHANGI\Jason Chang\Work\Others\code\log_to_file\package\log_to_file\log_to_file.py", line 36, in call_function
    return function()
           ¢| <function <lambda> at 0x00000176E66496A8>

  File "D:/Users/JCHANGI/Jason Chang/Work/Others/code/log_to_file/some_module_caller_example.py", line 18, in <lambda>
    everything_you_want_to_see = log_to_file(lambda : main(), print_opt = 0)
    ¢x                            ¢x                    ¢| <function main at 0x00000176E6690378>
    ¢x                            ¢| <function log_to_file at 0x00000176E670D268>
    ¢| None

  File "D:/Users/JCHANGI/Jason Chang/Work/Others/code/log_to_file/some_module_caller_example.py", line 10, in main
    test_function(number)
    ¢x             ¢| 10
    ¢| <function test_function at 0x00000176E670D2F0>

  File "D:\Users\JCHANGI\Jason Chang\Work\Others\code\log_to_file\some_module.py", line 14, in test_function
    1/0

ZeroDivisionError: division by zero
########################################################################################################################
2019-10-31 10:16:11.125 | INFO  | some_module               : test_function        : 12   | 0
2019-10-31 10:16:11.125 | INFO  | some_module               : test_function        : 12   | 1
2019-10-31 10:16:11.125 | INFO  | some_module               : test_function        : 12   | 2
2019-10-31 10:16:11.125 | INFO  | some_module               : test_function        : 12   | 3
2019-10-31 10:16:11.125 | INFO  | some_module               : test_function        : 12   | 4
2019-10-31 10:16:11.125 | INFO  | some_module               : test_function        : 12   | 5
2019-10-31 10:16:11.125 | INFO  | some_module               : test_function        : 12   | 6
2019-10-31 10:16:11.125 | INFO  | some_module               : test_function        : 12   | 7
2019-10-31 10:16:11.126 | INFO  | some_module               : test_function        : 12   | 8
2019-10-31 10:16:11.126 | INFO  | some_module               : test_function        : 12   | 9
2019-10-31 10:16:12.127 | ERROR | log_to_file               : log_to_file          : 99   | An error has been caught in function 'log_to_file', process 'MainProcess' (25104), thread 'MainThread' (18224):
Traceback (most recent call last):

  File "D:\Users\JCHANGI\Jason Chang\Work\Others\code\log_to_file\package\log_to_file\log_to_file.py", line 99, in log_to_file
    everything_you_want_to_see = call_function(function)
                                 ¢x             ¢| <function <lambda> at 0x00000176E6690378>
                                 ¢| <function call_function at 0x00000176E6601268>

  File "D:\Users\JCHANGI\Jason Chang\Work\Others\code\log_to_file\package\log_to_file\log_to_file.py", line 36, in call_function
    return function()
           ¢| <function <lambda> at 0x00000176E6690378>

  File "D:/Users/JCHANGI/Jason Chang/Work/Others/code/log_to_file/some_module_caller_example.py", line 18, in <lambda>
    everything_you_want_to_see = log_to_file(lambda : main(), print_opt = 0)
    ¢x                            ¢x                    ¢| <function main at 0x00000176E66C90D0>
    ¢x                            ¢| <function log_to_file at 0x00000176E661ED08>
    ¢| None

  File "D:/Users/JCHANGI/Jason Chang/Work/Others/code/log_to_file/some_module_caller_example.py", line 10, in main
    test_function(number)
    ¢x             ¢| 10
    ¢| <function test_function at 0x00000176E53FE6A8>

  File "D:\Users\JCHANGI\Jason Chang\Work\Others\code\log_to_file\some_module.py", line 14, in test_function
    1/0

ZeroDivisionError: division by zero
########################################################################################################################
2019-10-31 10:47:41.704 | INFO  | some_module               : test_function        : 12   | 0
2019-10-31 10:47:41.704 | INFO  | some_module               : test_function        : 12   | 1
2019-10-31 10:47:41.704 | INFO  | some_module               : test_function        : 12   | 2
2019-10-31 10:47:41.705 | INFO  | some_module               : test_function        : 12   | 3
2019-10-31 10:47:41.705 | INFO  | some_module               : test_function        : 12   | 4
2019-10-31 10:47:41.705 | INFO  | some_module               : test_function        : 12   | 5
2019-10-31 10:47:41.705 | INFO  | some_module               : test_function        : 12   | 6
2019-10-31 10:47:41.705 | INFO  | some_module               : test_function        : 12   | 7
2019-10-31 10:47:41.705 | INFO  | some_module               : test_function        : 12   | 8
2019-10-31 10:47:41.705 | INFO  | some_module               : test_function        : 12   | 9
2019-10-31 10:47:42.707 | ERROR | log_to_file               : log_to_file          : 110  | An error has been caught in function 'log_to_file', process 'MainProcess' (24604), thread 'MainThread' (14492):
Traceback (most recent call last):

  File "D:\Users\JCHANGI\Jason Chang\Work\Others\code\log_to_file\package\log_to_file\log_to_file.py", line 110, in log_to_file
    everything_you_want_to_see = call_function(function)
                                 ¢x             ¢| <function <lambda> at 0x000001E0CD54FE18>
                                 ¢| <function call_function at 0x000001E0CD542510>

  File "D:\Users\JCHANGI\Jason Chang\Work\Others\code\log_to_file\package\log_to_file\log_to_file.py", line 47, in call_function
    return function()
           ¢| <function <lambda> at 0x000001E0CD54FE18>

  File "D:/Users/JCHANGI/Jason Chang/Work/Others/code/log_to_file/some_module_caller_example.py", line 18, in <lambda>
    everything_you_want_to_see = log_to_file(lambda : main(), print_opt = 0)
                                 ¢x                    ¢| <function main at 0x000001E0CD194E18>
                                 ¢| <function log_to_file at 0x000001E0CD5427B8>

  File "D:/Users/JCHANGI/Jason Chang/Work/Others/code/log_to_file/some_module_caller_example.py", line 10, in main
    test_function(number)
    ¢x             ¢| 10
    ¢| <function test_function at 0x000001E0CD542840>

  File "D:\Users\JCHANGI\Jason Chang\Work\Others\code\log_to_file\some_module.py", line 14, in test_function
    1/0

ZeroDivisionError: division by zero
########################################################################################################################
2019-10-31 10:48:58.457 | INFO  | some_module               : test_function        : 12   | 0
2019-10-31 10:48:58.457 | INFO  | some_module               : test_function        : 12   | 1
2019-10-31 10:48:58.458 | INFO  | some_module               : test_function        : 12   | 2
2019-10-31 10:48:58.458 | INFO  | some_module               : test_function        : 12   | 3
2019-10-31 10:48:58.458 | INFO  | some_module               : test_function        : 12   | 4
2019-10-31 10:48:58.458 | INFO  | some_module               : test_function        : 12   | 5
2019-10-31 10:48:58.458 | INFO  | some_module               : test_function        : 12   | 6
2019-10-31 10:48:58.458 | INFO  | some_module               : test_function        : 12   | 7
2019-10-31 10:48:58.458 | INFO  | some_module               : test_function        : 12   | 8
2019-10-31 10:48:58.458 | INFO  | some_module               : test_function        : 12   | 9
2019-10-31 10:48:59.460 | ERROR | log_to_file               : log_to_file          : 111  | An error has been caught in function 'log_to_file', process 'MainProcess' (24604), thread 'MainThread' (14492):
Traceback (most recent call last):

  File "D:\Users\JCHANGI\Jason Chang\Work\Others\code\log_to_file\package\log_to_file\log_to_file.py", line 111, in log_to_file
    everything_you_want_to_see = call_function(function)
                                 ¢x             ¢| <function <lambda> at 0x000001E0CD194E18>
                                 ¢| <function call_function at 0x000001E0CD7FBC80>

  File "D:\Users\JCHANGI\Jason Chang\Work\Others\code\log_to_file\package\log_to_file\log_to_file.py", line 48, in call_function
    return function()
           ¢| <function <lambda> at 0x000001E0CD194E18>

  File "D:/Users/JCHANGI/Jason Chang/Work/Others/code/log_to_file/some_module_caller_example.py", line 18, in <lambda>
    everything_you_want_to_see = log_to_file(lambda : main(), print_opt = 0)
    ¢x                            ¢x                    ¢| <function main at 0x000001E0CD542488>
    ¢x                            ¢| <function log_to_file at 0x000001E0CD7FBF28>
    ¢| None

  File "D:/Users/JCHANGI/Jason Chang/Work/Others/code/log_to_file/some_module_caller_example.py", line 10, in main
    test_function(number)
    ¢x             ¢| 10
    ¢| <function test_function at 0x000001E0CD64A2F0>

  File "D:\Users\JCHANGI\Jason Chang\Work\Others\code\log_to_file\some_module.py", line 14, in test_function
    1/0

ZeroDivisionError: division by zero
########################################################################################################################
2019-10-31 10:52:19.343 | INFO  | some_module               : test_function        : 12   | 0
2019-10-31 10:52:19.344 | INFO  | some_module               : test_function        : 12   | 1
2019-10-31 10:52:19.344 | INFO  | some_module               : test_function        : 12   | 2
2019-10-31 10:52:19.344 | INFO  | some_module               : test_function        : 12   | 3
2019-10-31 10:52:19.344 | INFO  | some_module               : test_function        : 12   | 4
2019-10-31 10:52:19.344 | INFO  | some_module               : test_function        : 12   | 5
2019-10-31 10:52:19.344 | INFO  | some_module               : test_function        : 12   | 6
2019-10-31 10:52:19.344 | INFO  | some_module               : test_function        : 12   | 7
2019-10-31 10:52:19.344 | INFO  | some_module               : test_function        : 12   | 8
2019-10-31 10:52:19.345 | INFO  | some_module               : test_function        : 12   | 9
2019-10-31 10:52:20.347 | ERROR | log_to_file               : log_to_file          : 111  | An error has been caught in function 'log_to_file', process 'MainProcess' (24748), thread 'MainThread' (24600):
Traceback (most recent call last):

  File "D:\Users\JCHANGI\Jason Chang\Work\Others\code\log_to_file\package\log_to_file\log_to_file.py", line 111, in log_to_file
    everything_you_want_to_see = call_function(function)
                                 ¢x             ¢| <function <lambda> at 0x0000026135BDBEA0>
                                 ¢| <function call_function at 0x0000026135BCC598>

  File "D:\Users\JCHANGI\Jason Chang\Work\Others\code\log_to_file\package\log_to_file\log_to_file.py", line 48, in call_function
    return function()
           ¢| <function <lambda> at 0x0000026135BDBEA0>

  File "D:/Users/JCHANGI/Jason Chang/Work/Others/code/log_to_file/some_module_caller_example.py", line 18, in <lambda>
    everything_you_want_to_see = log_to_file(lambda : main(), print_opt = 0)
                                 ¢x                    ¢| <function main at 0x00000261357F6730>
                                 ¢| <function log_to_file at 0x0000026135BCC840>

  File "D:/Users/JCHANGI/Jason Chang/Work/Others/code/log_to_file/some_module_caller_example.py", line 10, in main
    test_function(number)
    ¢x             ¢| 10
    ¢| <function test_function at 0x0000026135BCC8C8>

  File "D:\Users\JCHANGI\Jason Chang\Work\Others\code\log_to_file\some_module.py", line 14, in test_function
    1/0

ZeroDivisionError: division by zero
########################################################################################################################
2019-10-31 11:00:52.091 | INFO  | some_module               : test_function        : 12   | 0
2019-10-31 11:00:52.091 | INFO  | some_module               : test_function        : 12   | 1
2019-10-31 11:00:52.092 | INFO  | some_module               : test_function        : 12   | 2
2019-10-31 11:00:52.092 | INFO  | some_module               : test_function        : 12   | 3
2019-10-31 11:00:52.092 | INFO  | some_module               : test_function        : 12   | 4
2019-10-31 11:00:52.092 | INFO  | some_module               : test_function        : 12   | 5
2019-10-31 11:00:52.092 | INFO  | some_module               : test_function        : 12   | 6
2019-10-31 11:00:52.092 | INFO  | some_module               : test_function        : 12   | 7
2019-10-31 11:00:52.092 | INFO  | some_module               : test_function        : 12   | 8
2019-10-31 11:00:52.092 | INFO  | some_module               : test_function        : 12   | 9
2019-10-31 11:00:53.093 | ERROR | log_to_file               : log_to_file          : 109  | An error has been caught in function 'log_to_file', process 'MainProcess' (13036), thread 'MainThread' (21196):
Traceback (most recent call last):

  File "D:\Users\JCHANGI\Jason Chang\Work\Others\code\log_to_file\package\log_to_file\log_to_file.py", line 109, in log_to_file
    everything_you_want_to_see = call_function(function)
                                 ¢x             ¢| <function <lambda> at 0x0000020E6ECDC0D0>
                                 ¢| <function call_function at 0x0000020E6ECC6730>

  File "D:\Users\JCHANGI\Jason Chang\Work\Others\code\log_to_file\package\log_to_file\log_to_file.py", line 46, in call_function
    return function()
           ¢| <function <lambda> at 0x0000020E6ECDC0D0>

  File "D:/Users/JCHANGI/Jason Chang/Work/Others/code/log_to_file/some_module_caller_example.py", line 18, in <lambda>
    everything_you_want_to_see = log_to_file(lambda : main(), print_opt = 0)
                                 ¢x                    ¢| <function main at 0x0000020E6EB60EA0>
                                 ¢| <function log_to_file at 0x0000020E6ECC69D8>

  File "D:/Users/JCHANGI/Jason Chang/Work/Others/code/log_to_file/some_module_caller_example.py", line 10, in main
    test_function(number)
    ¢x             ¢| 10
    ¢| <function test_function at 0x0000020E6ECC6A60>

  File "D:\Users\JCHANGI\Jason Chang\Work\Others\code\log_to_file\some_module.py", line 14, in test_function
    1/0

ZeroDivisionError: division by zero
########################################################################################################################
2019-10-31 11:02:34.445 | INFO  | some_module               : test_function        : 12   | 0
2019-10-31 11:02:34.445 | INFO  | some_module               : test_function        : 12   | 1
2019-10-31 11:02:34.445 | INFO  | some_module               : test_function        : 12   | 2
2019-10-31 11:02:34.445 | INFO  | some_module               : test_function        : 12   | 3
2019-10-31 11:02:34.446 | INFO  | some_module               : test_function        : 12   | 4
2019-10-31 11:02:34.446 | INFO  | some_module               : test_function        : 12   | 5
2019-10-31 11:02:34.446 | INFO  | some_module               : test_function        : 12   | 6
2019-10-31 11:02:34.446 | INFO  | some_module               : test_function        : 12   | 7
2019-10-31 11:02:34.446 | INFO  | some_module               : test_function        : 12   | 8
2019-10-31 11:02:34.446 | INFO  | some_module               : test_function        : 12   | 9
2019-10-31 11:02:35.447 | ERROR | log_to_file               : log_to_file          : 109  | An error has been caught in function 'log_to_file', process 'MainProcess' (13036), thread 'MainThread' (21196):
Traceback (most recent call last):

  File "D:\Users\JCHANGI\Jason Chang\Work\Others\code\log_to_file\package\log_to_file\log_to_file.py", line 109, in log_to_file
    everything_you_want_to_see = call_function(function)
                                 ¢x             ¢| <function <lambda> at 0x0000020E6EB60EA0>
                                 ¢| <function call_function at 0x0000020E6EE1F7B8>

  File "D:\Users\JCHANGI\Jason Chang\Work\Others\code\log_to_file\package\log_to_file\log_to_file.py", line 46, in call_function
    return function()
           ¢| <function <lambda> at 0x0000020E6EB60EA0>

  File "D:/Users/JCHANGI/Jason Chang/Work/Others/code/log_to_file/some_module_caller_example.py", line 18, in <lambda>
    everything_you_want_to_see = log_to_file(lambda : main(), print_opt = 0)
    ¢x                            ¢x                    ¢| <function main at 0x0000020E6EB4A510>
    ¢x                            ¢| <function log_to_file at 0x0000020E6EE1FA60>
    ¢| None

  File "D:/Users/JCHANGI/Jason Chang/Work/Others/code/log_to_file/some_module_caller_example.py", line 10, in main
    test_function(number)
    ¢x             ¢| 10
    ¢| <function test_function at 0x0000020E6EE1FAE8>

  File "D:\Users\JCHANGI\Jason Chang\Work\Others\code\log_to_file\some_module.py", line 14, in test_function
    1/0

ZeroDivisionError: division by zero
########################################################################################################################
2019-10-31 11:07:41.431 | INFO  | some_module               : test_function        : 12   | 0
2019-10-31 11:07:41.432 | INFO  | some_module               : test_function        : 12   | 1
2019-10-31 11:07:41.432 | INFO  | some_module               : test_function        : 12   | 2
2019-10-31 11:07:41.432 | INFO  | some_module               : test_function        : 12   | 3
2019-10-31 11:07:41.432 | INFO  | some_module               : test_function        : 12   | 4
2019-10-31 11:07:41.432 | INFO  | some_module               : test_function        : 12   | 5
2019-10-31 11:07:41.432 | INFO  | some_module               : test_function        : 12   | 6
2019-10-31 11:07:41.432 | INFO  | some_module               : test_function        : 12   | 7
2019-10-31 11:07:41.432 | INFO  | some_module               : test_function        : 12   | 8
2019-10-31 11:07:41.433 | INFO  | some_module               : test_function        : 12   | 9
2019-10-31 11:07:42.434 | ERROR | log_to_file               : log_to_file          : 115  | An error has been caught in function 'log_to_file', process 'MainProcess' (24828), thread 'MainThread' (24612):
Traceback (most recent call last):

  File "D:\Users\JCHANGI\Jason Chang\Work\Others\code\log_to_file\package\log_to_file\log_to_file.py", line 115, in log_to_file
    everything_you_want_to_see = call_function(function)
                                 ¢x             ¢| <function <lambda> at 0x0000024C128EC158>
                                 ¢| <function call_function at 0x0000024C128D77B8>

  File "D:\Users\JCHANGI\Jason Chang\Work\Others\code\log_to_file\package\log_to_file\log_to_file.py", line 52, in call_function
    return function()
           ¢| <function <lambda> at 0x0000024C128EC158>

  File "D:/Users/JCHANGI/Jason Chang/Work/Others/code/log_to_file/some_module_caller_example.py", line 18, in <lambda>
    everything_you_want_to_see = log_to_file(lambda : main(), print_opt = 0)
                                 ¢x                    ¢| <function main at 0x0000024C1275A598>
                                 ¢| <function log_to_file at 0x0000024C128D7A60>

  File "D:/Users/JCHANGI/Jason Chang/Work/Others/code/log_to_file/some_module_caller_example.py", line 10, in main
    test_function(number)
    ¢x             ¢| 10
    ¢| <function test_function at 0x0000024C128D7AE8>

  File "D:\Users\JCHANGI\Jason Chang\Work\Others\code\log_to_file\some_module.py", line 14, in test_function
    1/0

ZeroDivisionError: division by zero
########################################################################################################################
2019-10-31 11:08:42.747 | INFO  | some_module               : test_function        : 12   | 0
2019-10-31 11:08:42.748 | INFO  | some_module               : test_function        : 12   | 1
2019-10-31 11:08:42.749 | INFO  | some_module               : test_function        : 12   | 2
2019-10-31 11:08:42.749 | INFO  | some_module               : test_function        : 12   | 3
2019-10-31 11:08:42.750 | INFO  | some_module               : test_function        : 12   | 4
2019-10-31 11:08:42.751 | INFO  | some_module               : test_function        : 12   | 5
2019-10-31 11:08:42.751 | INFO  | some_module               : test_function        : 12   | 6
2019-10-31 11:08:42.752 | INFO  | some_module               : test_function        : 12   | 7
2019-10-31 11:08:42.753 | INFO  | some_module               : test_function        : 12   | 8
2019-10-31 11:08:42.753 | INFO  | some_module               : test_function        : 12   | 9
2019-10-31 11:08:43.755 | ERROR | log_to_file               : log_to_file          : 115  | An error has been caught in function 'log_to_file', process 'MainProcess' (21240), thread 'MainThread' (16560):
Traceback (most recent call last):

  File "D:\Users\JCHANGI\Jason Chang\Work\Others\code\log_to_file\package\log_to_file\log_to_file.py", line 115, in log_to_file
    everything_you_want_to_see = call_function(function)
                                 ¢x             ¢| <function <lambda> at 0x0000016F790FC158>
                                 ¢| <function call_function at 0x0000016F790DF7B8>

  File "D:\Users\JCHANGI\Jason Chang\Work\Others\code\log_to_file\package\log_to_file\log_to_file.py", line 52, in call_function
    return function()
           ¢| <function <lambda> at 0x0000016F790FC158>

  File "D:/Users/JCHANGI/Jason Chang/Work/Others/code/log_to_file/some_module_caller_example.py", line 18, in <lambda>
    everything_you_want_to_see = log_to_file(lambda : main())
                                 ¢x                    ¢| <function main at 0x0000016F78C1E378>
                                 ¢| <function log_to_file at 0x0000016F790DFA60>

  File "D:/Users/JCHANGI/Jason Chang/Work/Others/code/log_to_file/some_module_caller_example.py", line 10, in main
    test_function(number)
    ¢x             ¢| 10
    ¢| <function test_function at 0x0000016F790DFAE8>

  File "D:\Users\JCHANGI\Jason Chang\Work\Others\code\log_to_file\some_module.py", line 14, in test_function
    1/0

ZeroDivisionError: division by zero
########################################################################################################################
2019-10-31 13:47:24.898 | INFO  | some_module               : test_function        : 12   | 0
2019-10-31 13:47:24.898 | INFO  | some_module               : test_function        : 12   | 1
2019-10-31 13:47:24.899 | INFO  | some_module               : test_function        : 12   | 2
2019-10-31 13:47:24.900 | INFO  | some_module               : test_function        : 12   | 3
2019-10-31 13:47:24.901 | INFO  | some_module               : test_function        : 12   | 4
2019-10-31 13:47:24.902 | INFO  | some_module               : test_function        : 12   | 5
2019-10-31 13:47:24.903 | INFO  | some_module               : test_function        : 12   | 6
2019-10-31 13:47:24.903 | INFO  | some_module               : test_function        : 12   | 7
2019-10-31 13:47:24.904 | INFO  | some_module               : test_function        : 12   | 8
2019-10-31 13:47:24.905 | INFO  | some_module               : test_function        : 12   | 9
2019-10-31 13:47:25.906 | ERROR | log_to_file               : log_to_file          : 164  | An error has been caught in function 'log_to_file', process 'MainProcess' (26408), thread 'MainThread' (19964):
Traceback (most recent call last):

  File "D:\Users\JCHANGI\Jason Chang\Work\Others\code\log_to_file\package\log_to_file\log_to_file.py", line 164, in log_to_file
    everything_you_want_to_see = call_function(function)
                                 ¢x             ¢| <function <lambda> at 0x000001EC81ECDE18>
                                 ¢| <function call_function at 0x000001EC81EB2510>

  File "D:\Users\JCHANGI\Jason Chang\Work\Others\code\log_to_file\package\log_to_file\log_to_file.py", line 52, in call_function
    return function()
           ¢| <function <lambda> at 0x000001EC81ECDE18>

  File "D:/Users/JCHANGI/Jason Chang/Work/Others/code/log_to_file/some_module_caller_example.py", line 19, in <lambda>
    log_to_file(lambda : main(), DB_OPTION = True, \
    ¢x                    ¢| <function main at 0x000001EC81AAC8C8>
    ¢| <function log_to_file at 0x000001EC81EB27B8>

  File "D:/Users/JCHANGI/Jason Chang/Work/Others/code/log_to_file/some_module_caller_example.py", line 10, in main
    test_function(number)
    ¢x             ¢| 10
    ¢| <function test_function at 0x000001EC81EB2840>

  File "D:\Users\JCHANGI\Jason Chang\Work\Others\code\log_to_file\some_module.py", line 14, in test_function
    1/0

ZeroDivisionError: division by zero
########################################################################################################################
2019-10-31 13:47:56.578 | INFO  | some_module               : test_function        : 12   | 0
2019-10-31 13:47:56.579 | INFO  | some_module               : test_function        : 12   | 1
2019-10-31 13:47:56.580 | INFO  | some_module               : test_function        : 12   | 2
2019-10-31 13:47:56.581 | INFO  | some_module               : test_function        : 12   | 3
2019-10-31 13:47:56.582 | INFO  | some_module               : test_function        : 12   | 4
2019-10-31 13:47:56.583 | INFO  | some_module               : test_function        : 12   | 5
2019-10-31 13:47:56.583 | INFO  | some_module               : test_function        : 12   | 6
2019-10-31 13:47:56.584 | INFO  | some_module               : test_function        : 12   | 7
2019-10-31 13:47:56.585 | INFO  | some_module               : test_function        : 12   | 8
2019-10-31 13:47:56.586 | INFO  | some_module               : test_function        : 12   | 9
2019-10-31 13:47:57.587 | ERROR | log_to_file               : log_to_file          : 164  | An error has been caught in function 'log_to_file', process 'MainProcess' (25560), thread 'MainThread' (24628):
Traceback (most recent call last):

  File "D:\Users\JCHANGI\Jason Chang\Work\Others\code\log_to_file\package\log_to_file\log_to_file.py", line 164, in log_to_file
    everything_you_want_to_see = call_function(function)
                                 ¢x             ¢| <function <lambda> at 0x0000022C466DCE18>
                                 ¢| <function call_function at 0x0000022C466C2510>

  File "D:\Users\JCHANGI\Jason Chang\Work\Others\code\log_to_file\package\log_to_file\log_to_file.py", line 52, in call_function
    return function()
           ¢| <function <lambda> at 0x0000022C466DCE18>

  File "D:/Users/JCHANGI/Jason Chang/Work/Others/code/log_to_file/some_module_caller_example.py", line 19, in <lambda>
    log_to_file(lambda : main(), DB_OPTION = True, \
    ¢x                    ¢| <function main at 0x0000022C46324AE8>
    ¢| <function log_to_file at 0x0000022C466C27B8>

  File "D:/Users/JCHANGI/Jason Chang/Work/Others/code/log_to_file/some_module_caller_example.py", line 10, in main
    test_function(number)
    ¢x             ¢| 10
    ¢| <function test_function at 0x0000022C466C2840>

  File "D:\Users\JCHANGI\Jason Chang\Work\Others\code\log_to_file\some_module.py", line 14, in test_function
    1/0

ZeroDivisionError: division by zero
########################################################################################################################
2019-10-31 14:03:31.288 | INFO  | some_module               : test_function        : 12   | 0
2019-10-31 14:03:31.289 | INFO  | some_module               : test_function        : 12   | 1
2019-10-31 14:03:31.290 | INFO  | some_module               : test_function        : 12   | 2
2019-10-31 14:03:31.291 | INFO  | some_module               : test_function        : 12   | 3
2019-10-31 14:03:31.292 | INFO  | some_module               : test_function        : 12   | 4
2019-10-31 14:03:31.293 | INFO  | some_module               : test_function        : 12   | 5
2019-10-31 14:03:31.293 | INFO  | some_module               : test_function        : 12   | 6
2019-10-31 14:03:31.294 | INFO  | some_module               : test_function        : 12   | 7
2019-10-31 14:03:31.295 | INFO  | some_module               : test_function        : 12   | 8
2019-10-31 14:03:31.296 | INFO  | some_module               : test_function        : 12   | 9
2019-10-31 14:03:32.297 | ERROR | log_to_file               : log_to_file          : 159  | An error has been caught in function 'log_to_file', process 'MainProcess' (22520), thread 'MainThread' (10440):
Traceback (most recent call last):

  File "D:\Users\JCHANGI\Jason Chang\Work\Others\code\log_to_file\package\log_to_file\log_to_file.py", line 159, in log_to_file
    everything_you_want_to_see = call_function(function)
                                 ¢x             ¢| <function <lambda> at 0x000001D04C02E0D0>
                                 ¢| <function call_function at 0x000001D04C017730>

  File "D:\Users\JCHANGI\Jason Chang\Work\Others\code\log_to_file\package\log_to_file\log_to_file.py", line 52, in call_function
    return function()
           ¢| <function <lambda> at 0x000001D04C02E0D0>

  File "D:/Users/JCHANGI/Jason Chang/Work/Others/code/log_to_file/some_module_caller_example.py", line 19, in <lambda>
    log_to_file(lambda : main(), DB_OPTION = True, \
    ¢x                    ¢| <function main at 0x000001D04BE9A1E0>
    ¢| <function log_to_file at 0x000001D04C0179D8>

  File "D:/Users/JCHANGI/Jason Chang/Work/Others/code/log_to_file/some_module_caller_example.py", line 10, in main
    test_function(number)
    ¢x             ¢| 10
    ¢| <function test_function at 0x000001D04C017A60>

  File "D:\Users\JCHANGI\Jason Chang\Work\Others\code\log_to_file\some_module.py", line 14, in test_function
    1/0

ZeroDivisionError: division by zero
########################################################################################################################
2019-10-31 14:05:40.928 | INFO  | some_module               : test_function        : 12   | 0
2019-10-31 14:05:40.928 | INFO  | some_module               : test_function        : 12   | 1
2019-10-31 14:05:40.929 | INFO  | some_module               : test_function        : 12   | 2
2019-10-31 14:05:40.930 | INFO  | some_module               : test_function        : 12   | 3
2019-10-31 14:05:40.930 | INFO  | some_module               : test_function        : 12   | 4
2019-10-31 14:05:40.931 | INFO  | some_module               : test_function        : 12   | 5
2019-10-31 14:05:40.931 | INFO  | some_module               : test_function        : 12   | 6
2019-10-31 14:05:40.932 | INFO  | some_module               : test_function        : 12   | 7
2019-10-31 14:05:40.933 | INFO  | some_module               : test_function        : 12   | 8
2019-10-31 14:05:40.934 | INFO  | some_module               : test_function        : 12   | 9
2019-10-31 14:05:41.935 | ERROR | log_to_file               : log_to_file          : 160  | An error has been caught in function 'log_to_file', process 'MainProcess' (22520), thread 'MainThread' (10440):
Traceback (most recent call last):

  File "D:\Users\JCHANGI\Jason Chang\Work\Others\code\log_to_file\package\log_to_file\log_to_file.py", line 160, in log_to_file
    everything_you_want_to_see = call_function(function)
                                 ¢x             ¢| <function <lambda> at 0x000001D04BE9A1E0>
                                 ¢| <function call_function at 0x000001D04C017840>

  File "D:\Users\JCHANGI\Jason Chang\Work\Others\code\log_to_file\package\log_to_file\log_to_file.py", line 52, in call_function
    return function()
           ¢| <function <lambda> at 0x000001D04BE9A1E0>

  File "D:/Users/JCHANGI/Jason Chang/Work/Others/code/log_to_file/some_module_caller_example.py", line 19, in <lambda>
    log_to_file(lambda : main(), DB_OPTION = True, \
    ¢x                    ¢| <function main at 0x000001D04C0176A8>
    ¢| <function log_to_file at 0x000001D04C163EA0>

  File "D:/Users/JCHANGI/Jason Chang/Work/Others/code/log_to_file/some_module_caller_example.py", line 10, in main
    test_function(number)
    ¢x             ¢| 10
    ¢| <function test_function at 0x000001D04C163F28>

  File "D:\Users\JCHANGI\Jason Chang\Work\Others\code\log_to_file\some_module.py", line 14, in test_function
    1/0

ZeroDivisionError: division by zero
