########################################################################################################################
2019-09-18 16:32:17.533 | INFO  | sub_program : test_function        : 11   | 0
2019-09-18 16:32:17.534 | INFO  | sub_program : test_function        : 11   | 1
2019-09-18 16:32:17.535 | INFO  | sub_program : test_function        : 11   | 2
2019-09-18 16:32:17.535 | INFO  | sub_program : test_function        : 11   | 3
2019-09-18 16:32:17.536 | INFO  | sub_program : test_function        : 11   | 4
2019-09-18 16:32:17.537 | INFO  | sub_program : test_function        : 11   | 5
2019-09-18 16:32:17.539 | INFO  | sub_program : test_function        : 11   | 6
2019-09-18 16:32:17.540 | INFO  | sub_program : test_function        : 11   | 7
2019-09-18 16:32:17.545 | INFO  | sub_program : test_function        : 11   | 8
2019-09-18 16:32:17.545 | INFO  | sub_program : test_function        : 11   | 9
2019-09-18 16:32:18.547 | ERROR | __main__   : <module>             : 20   | An error has been caught in function '<module>', process 'MainProcess' (16588), thread 'MainThread' (16244):
Traceback (most recent call last):

  File "D:/Users/JCHANGI/Jason Chang/Doc/Others/code/backup/log_template_2/caller_example.py", line 20, in <module>
    everything_you_want_to_see = main()
                                 ¢| <function main at 0x00000207D9FE7AE8>

  File "D:/Users/JCHANGI/Jason Chang/Doc/Others/code/backup/log_template_2/caller_example.py", line 12, in main
    test_function(number)
    ¢x             ¢| 10
    ¢| <function test_function at 0x00000207D9FE7950>

  File "D:\Users\JCHANGI\Jason Chang\Doc\Others\code\backup\log_template_2\sub_program.py", line 13, in test_function
    1/0

ZeroDivisionError: division by zero
