2020-11-26 11:20:55.568 | INFO  | __main__                                      : some_block                                    : 97    | block before: 1
2020-11-26 11:20:58.599 | INFO  | __main__                                      : some_block_inner                              : 89    | inner block before: 1
2020-11-26 11:20:58.599 | ERROR | log_to_file                                   : log_to_file                                   : 186   | An error has been caught in function 'log_to_file', process 'MainProcess' (13976), thread 'MainThread' (7856):
Traceback (most recent call last):

  File "G:\My Drive\Git\Useful-Python-Code\package\log_to_file_\log_to_file.py", line 186, in log_to_file
    output_of_function = call_function_with_catch_and_default(function)
                         ¢x                                    ¢| <function log_to_file_for_class.<locals>.decorator.<locals>.wrapper.<locals>.<lambda> at 0x000001FD02079AF0>
                         ¢| <function call_function_with_catch_and_default at 0x000001FD01F0B700>

  File "G:\My Drive\Git\Useful-Python-Code\package\log_to_file_\log_to_file.py", line 31, in call_function_with_catch_and_default
    return function()
           ¢| <function log_to_file_for_class.<locals>.decorator.<locals>.wrapper.<locals>.<lambda> at 0x000001FD02079AF0>

  File "G:\My Drive\Git\Useful-Python-Code\package\log_to_file_\log_to_file.py", line 115, in <lambda>
    result = log_to_file(lambda : function(*args, **kwargs), _reraise, _enable_file, _file_path, _overwrite_file)
             ¢x                    ¢x         ¢x       ¢| {}
             ¢x                    ¢x         ¢| (<__main__.some_block_class object at 0x000001FD01F10850>, 1)
             ¢x                    ¢| <function some_block_class.some_block_inner at 0x000001FD01F0BE50>
             ¢| <function log_to_file at 0x000001FD01F0B940>

  File "G:\My Drive\Git\Useful-Python-Code\package\log_to_file_\log_to_file_caller_example.py", line 90, in some_block_inner
    raise Exception("Inner error")

Exception: Inner error
2020-11-26 11:21:01.599 | ERROR | log_to_file                                   : log_to_file                                   : 186   | An error has been caught in function 'log_to_file', process 'MainProcess' (13976), thread 'MainThread' (7856):
Traceback (most recent call last):

  File "G:\My Drive\Git\Useful-Python-Code\package\log_to_file_\log_to_file.py", line 186, in log_to_file
    output_of_function = call_function_with_catch_and_default(function)
                         ¢x                                    ¢| <function log_to_file_for_func.<locals>.decorator.<locals>.wrapper.<locals>.<lambda> at 0x000001FD00196D30>
                         ¢| <function call_function_with_catch_and_default at 0x000001FD01F0B700>

  File "G:\My Drive\Git\Useful-Python-Code\package\log_to_file_\log_to_file.py", line 31, in call_function_with_catch_and_default
    return function()
           ¢| <function log_to_file_for_func.<locals>.decorator.<locals>.wrapper.<locals>.<lambda> at 0x000001FD00196D30>

  File "G:\My Drive\Git\Useful-Python-Code\package\log_to_file_\log_to_file.py", line 54, in <lambda>
    result = log_to_file(lambda : function(*args, **kwargs), reraise, enable_file, file_path, overwrite_file)
             ¢x                    ¢x         ¢x       ¢| {}
             ¢x                    ¢x         ¢| (<__main__.some_block_class object at 0x000001FD01F10850>, 1)
             ¢x                    ¢| <function some_block_class.some_block at 0x000001FD01F0BF70>
             ¢| <function log_to_file at 0x000001FD01F0B940>

  File "G:\My Drive\Git\Useful-Python-Code\package\log_to_file_\log_to_file_caller_example.py", line 105, in some_block
    test = 1/0

ZeroDivisionError: division by zero
